Workbook

Sheet README
A1: Texture census
A2: Log every background texture and FX sound in a handful of tracks, to find out how the era really used them.
A3: The Summary sheet turns the log into numbers: events per 8 bars by section, how many land on phrase lines, typical lengths, materials per genre.
A5: How to fill it in
A6: 1. Tracks: one row per track. Enter its BPM and the time of its first downbeat (bar 1) in seconds, so bars compute from times.
A7: 2. Sections: the section boundaries of each track, in bars (first and last bar). This is what turns counts into densities.
A8: 3. Log: one row per texture event while you listen. Type the time from your player as minutes and seconds.
A9: If you already know the bar, type it under Bar and leave the time empty.
A10: Beds and motion: one row per stretch, with its length. Ear candy and punctuation: one row per occurrence.
A11: 4. Leave the grey columns alone: they are formulas.
A12: 5. The blue EX rows are an example. The summary ignores them; delete them whenever you like.
A14: Legend
... A40: Time budget: about 20-30 minutes a track. Six to ten tracks is enough to see the pattern.

Sheet Log
A1: Track | B1: Min | C1: Sec | D1: Bar | E1: Length (s) | F1: Section | G1: Role | H1: Material | I1: Movement | J1: Space | K1: Level | L1: Variation | M1: Description | N1: How it might be made | O1: Genre | P1: BPM | Q1: Start (bars) | R1: Bar | S1: Beat | T1: Length (bars) | U1: Starts on | V1: Ends on
A2: EX | B2: 0 | C2: 56.2 | E2: 55.7 | F2: Intro | G2: Bed | H2: Noise | I2: Static | J2: Wide / panned | K2: Background | L2: Repeats same | M2: Filtered noise 'air' under the intro drums | N2: Pink noise, HP about 2 kHz, slow LFO on level | O2: =IF(A2="","",IFERROR(INDEX(Tracks!$E$2:$E$41,MATCH(A2,Tracks!$A$2:$A$41,0)),"?")) -> Example | P2: =IF(A2="","",IFERROR(N(INDEX(Tracks!$F$2:$F$41,MATCH(A2,Tracks!$A$2:$A$41,0))),"")) -> 138 | Q2: =IF(D2<>"",D2-1,IF(OR(A2="",C2="",N(P2)<=0),"",(N(B2)*60+C2-IFERROR(N(INDEX(Tracks!$G$2:$G$41,MATCH(A2,Tracks!$A$2:$A$41,0))),0))*P2/240)) -> 32.0275 | R2: =IF(Q2="","",INT(Q2)+1) -> 33 | S2: =IF(OR(Q2="",D2<>""),"",MIN(4.75,ROUND((Q2-INT(Q2))*16,0)/4+1)) -> 1 | T2: =IF(OR(E2="",N(P2)<=0),"",E2*P2/240) -> 32.0275 | U2: =IF(Q2="","",IF(MIN(MOD(Q2,32),32-MOD(Q2,32))<=0.25,32,IF(MIN(MOD(Q2,16),16-MOD(Q2,16))<=0.25,16,IF(MIN(MOD(Q2,8),8-MOD(Q2,8))<=0.25,8,"")))) -> 32 | V2: =IF(OR(Q2="",T2=""),"",IF(MIN(MOD((Q2+T2),32),32-MOD((Q2+T2),32))<=0.25,32,IF(MIN(MOD((Q2+T2),16),16-MOD((Q2+T2),16))<=0.25,16,IF(MIN(MOD((Q2+T2),8),8-MOD((Q2+T2),8))<=0.25,8,"")))) -> 32
A3: EX | B3: 3 | C3: 15.3 | E3: 13.9 | F3: Build | G3: Transition | H3: Noise | I3: Up | J3: Reverb | K3: Mid | L3: One-off | M3: White-noise sweep up into the drop | N3: Noise into BP, cutoff ramp over 8 bars, long reverb | O3: =IF(A3="","",IFERROR(INDEX(Tracks!$E$2:$E$41,MATCH(A3,Tracks!$A$2:$A$41,0)),"?")) -> Example | P3: =IF(A3="","",IFERROR(N(INDEX(Tracks!$F$2:$F$41,MATCH(A3,Tracks!$A$2:$A$41,0))),"")) -> 138 | Q3: =IF(D3<>"",D3-1,IF(OR(A3="",C3="",N(P3)<=0),"",(N(B3)*60+C3-IFERROR(N(INDEX(Tracks!$G$2:$G$41,MATCH(A3,Tracks!$A$2:$A$41,0))),0))*P3/240)) -> 112.01 | R3: =IF(Q3="","",INT(Q3)+1) -> 113 | S3: =IF(OR(Q3="",D3<>""),"",MIN(4.75,ROUND((Q3-INT(Q3))*16,0)/4+1)) -> 1 | T3: =IF(OR(E3="",N(P3)<=0),"",E3*P3/240) -> 7.9925 | U3: =IF(Q3="","",IF(MIN(MOD(Q3,32),32-MOD(Q3,32))<=0.25,32,IF(MIN(MOD(Q3,16),16-MOD(Q3,16))<=0.25,16,IF(MIN(MOD(Q3,8),8-MOD(Q3,8))<=0.25,8,"")))) -> 16 | V3: =IF(OR(Q3="",T3=""),"",IF(MIN(MOD((Q3+T3),32),32-MOD((Q3+T3),32))<=0.25,32,IF(MIN(MOD((Q3+T3),16),16-MOD((Q3+T3),16))<=0.25,16,IF(MIN(MOD((Q3+T3),8),8-MOD((Q3+T3),8))<=0.25,8,"")))) -> 8
A4: EX | B4: 4 | C4: 2.6 | E4: 0.4 | F4: Drop | G4: Ear candy | H4: Inharmonic | I4: Down | J4: Delay throw | K4: Mid | L4: Repeats varied | M4: Ring-mod zap, panned left, different pitch each time | N4: Ring mod or FM, fast pitch drop, into the ping-pong | O4: =IF(A4="","",IFERROR(INDEX(Tracks!$E$2:$E$41,MATCH(A4,Tracks!$A$2:$A$41,0)),"?")) -> Example | P4: =IF(A4="","",IFERROR(N(INDEX(Tracks!$F$2:$F$41,MATCH(A4,Tracks!$A$2:$A$41,0))),"")) -> 138 | Q4: =IF(D4<>"",D4-1,IF(OR(A4="",C4="",N(P4)<=0),"",(N(B4)*60+C4-IFERROR(N(INDEX(Tracks!$G$2:$G$41,MATCH(A4,Tracks!$A$2:$A$41,0))),0))*P4/240)) -> 139.2075 | R4: =IF(Q4="","",INT(Q4)+1) -> 140 | S4: =IF(OR(Q4="",D4<>""),"",MIN(4.75,ROUND((Q4-INT(Q4))*16,0)/4+1)) -> 1.75 | T4: =IF(OR(E4="",N(P4)<=0),"",E4*P4/240) -> 0.23 | U4: =IF(Q4="","",IF(MIN(MOD(Q4,32),32-MOD(Q4,32))<=0.25,32,IF(MIN(MOD(Q4,16),16-MOD(Q4,16))<=0.25,16,IF(MIN(MOD(Q4,8),8-MOD(Q4,8))<=0.25,8,"")))) | V4: =IF(OR(Q4="",T4=""),"",IF(MIN(MOD((Q4+T4),32),32-MOD((Q4+T4),32))<=0.25,32,IF(MIN(MOD((Q4+T4),16),16-MOD((Q4+T4),16))<=0.25,16,IF(MIN(MOD((Q4+T4),8),8-MOD((Q4+T4),8))<=0.25,8,""))))
O5: =IF(A5="","",IFERROR(INDEX(Tracks!$E$2:$E$41,MATCH(A5,Tracks!$A$2:$A$41,0)),"?")) | P5: =IF(A5="","",IFERROR(N(INDEX(Tracks!$F$2:$F$41,MATCH(A5,Tracks!$A$2:$A$41,0))),"")) | Q5: =IF(D5<>"",D5-1,IF(OR(A5="",C5="",N(P5)<=0),"",(N(B5)*60+C5-IFERROR(N(INDEX(Tracks!$G$2:$G$41,MATCH(A5,Tracks!$A$2:$A$41,0))),0))*P5/240)) | R5: =IF(Q5="","",INT(Q5)+1) | S5: =IF(OR(Q5="",D5<>""),"",MIN(4.75,ROUND((Q5-INT(Q5))*16,0)/4+1)) | T5: =IF(OR(E5="",N(P5)<=0),"",E5*P5/240) | U5: =IF(Q5="","",IF(MIN(MOD(Q5,32),32-MOD(Q5,32))<=0.25,32,IF(MIN(MOD(Q5,16),16-MOD(Q5,16))<=0.25,16,IF(MIN(MOD(Q5,8),8-MOD(Q5,8))<=0.25,8,"")))) | V5: =IF(OR(Q5="",T5=""),"",IF(MIN(MOD((Q5+T5),32),32-MOD((Q5+T5),32))<=0.25,32,IF(MIN(MOD((Q5+T5),16),16-MOD((Q5+T5),16))<=0.25,16,IF(MIN(MOD((Q5+T5),8),8-MOD((Q5+T5),8))<=0.25,8,""))))
O6: =IF(A6="","",IFERROR(INDEX(Tracks!$E$2:$E$41,MATCH(A6,Tracks!$A$2:$A$41,0)),"?")) | P6: =IF(A6="","",IFERROR(N(INDEX(Tracks!$F$2:$F$41,MATCH(A6,Tracks!$A$2:$A$41,0))),"")) | Q6: =IF(D6<>"",D6-1,IF(OR(A6="",C6="",N(P6)<=0),"",(N(B6)*60+C6-IFERROR(N(INDEX(Tracks!$G$2:$G$41,MATCH(A6,Tracks!$A$2:$A$41,0))),0))*P6/240)) | R6: =IF(Q6="","",INT(Q6)+1) | S6: =IF(OR(Q6="",D6<>""),"",MIN(4.75,ROUND((Q6-INT(Q6))*16,0)/4+1)) | T6: =IF(OR(E6="",N(P6)<=0),"",E6*P6/240) | U6: =IF(Q6="","",IF(MIN(MOD(Q6,32),32-MOD(Q6,32))<=0.25,32,IF(MIN(MOD(Q6,16),16-MOD(Q6,16))<=0.25,16,IF(MIN(MOD(Q6,8),8-MOD(Q6,8))<=0.25,8,"")))) | V6: =IF(OR(Q6="",T6=""),"",IF(MIN(MOD((Q6+T6),32),32-MOD((Q6+T6),32))<=0.25,32,IF(MIN(MOD((Q6+T6),16),16-MOD((Q6+T6),16))<=0.25,16,IF(MIN(MOD((Q6+T6),8),8-MOD((Q6+T6),8))<=0.25,8,""))))
O7: =IF(A7="","",IFERROR(INDEX(Tracks!$E$2:$E$41,MATCH(A7,Tracks!$A$2:$A$41,0)),"?")) | P7: =IF(A7="","",IFERROR(N(INDEX(Tracks!$F$2:$F$41,MATCH(A7,Tracks!$A$2:$A$41,0))),"")) | Q7: =IF(D7<>"",D7-1,IF(OR(A7="",C7="",N(P7)<=0),"",(N(B7)*60+C7-IFERROR(N(INDEX(Tracks!$G$2:$G$41,MATCH(A7,Tracks!$A$2:$A$41,0))),0))*P7/240)) | R7: =IF(Q7="","",INT(Q7)+1) | S7: =IF(OR(Q7="",D7<>""),"",MIN(4.75,ROUND((Q7-INT(Q7))*16,0)/4+1)) | T7: =IF(OR(E7="",N(P7)<=0),"",E7*P7/240) | U7: =IF(Q7="","",IF(MIN(MOD(Q7,32),32-MOD(Q7,32))<=0.25,32,IF(MIN(MOD(Q7,16),16-MOD(Q7,16))<=0.25,16,IF(MIN(MOD(Q7,8),8-MOD(Q7,8))<=0.25,8,"")))) | V7: =IF(OR(Q7="",T7=""),"",IF(MIN(MOD((Q7+T7),32),32-MOD((Q7+T7),32))<=0.25,32,IF(MIN(MOD((Q7+T7),16),16-MOD((Q7+T7),16))<=0.25,16,IF(MIN(MOD((Q7+T7),8),8-MOD((Q7+T7),8))<=0.25,8,""))))
O8: =IF(A8="","",IFERROR(INDEX(Tracks!$E$2:$E$41,MATCH(A8,Tracks!$A$2:$A$41,0)),"?")) | P8: =IF(A8="","",IFERROR(N(INDEX(Tracks!$F$2:$F$41,MATCH(A8,Tracks!$A$2:$A$41,0))),"")) | Q8: =IF(D8<>"",D8-1,IF(OR(A8="",C8="",N(P8)<=0),"",(N(B8)*60+C8-IFERROR(N(INDEX(Tracks!$G$2:$G$41,MATCH(A8,Tracks!$A$2:$A$41,0))),0))*P8/240)) | R8: =IF(Q8="","",INT(Q8)+1) | S8: =IF(OR(Q8="",D8<>""),"",MIN(4.75,ROUND((Q8-INT(Q8))*16,0)/4+1)) | T8: =IF(OR(E8="",N(P8)<=0),"",E8*P8/240) | U8: =IF(Q8="","",IF(MIN(MOD(Q8,32),32-MOD(Q8,32))<=0.25,32,IF(MIN(MOD(Q8,16),16-MOD(Q8,16))<=0.25,16,IF(MIN(MOD(Q8,8),8-MOD(Q8,8))<=0.25,8,"")))) | V8: =IF(OR(Q8="",T8=""),"",IF(MIN(MOD((Q8+T8),32),32-MOD((Q8+T8),32))<=0.25,32,IF(MIN(MOD((Q8+T8),16),16-MOD((Q8+T8),16))<=0.25,16,IF(MIN(MOD((Q8+T8),8),8-MOD((Q8+T8),8))<=0.25,8,""))))
O9: =IF(A9="","",IFERROR(INDEX(Tracks!$E$2:$E$41,MATCH(A9,Tracks!$A$2:$A$41,0)),"?")) | P9: =IF(A9="","",IFERROR(N(INDEX(Tracks!$F$2:$F$41,MATCH(A9,Tracks!$A$2:$A$41,0))),"")) | Q9: =IF(D9<>"",D9-1,IF(OR(A9="",C9="",N(P9)<=0),"",(N(B9)*60+C9-IFERROR(N(INDEX(Tracks!$G$2:$G$41,MATCH(A9,Tracks!$A$2:$A$41,0))),0))*P9/240)) | R9: =IF(Q9="","",INT(Q9)+1) | S9: =IF(OR(Q9="",D9<>""),"",MIN(4.75,ROUND((Q9-INT(Q9))*16,0)/4+1)) | T9: =IF(OR(E9="",N(P9)<=0),"",E9*P9/240) | U9: =IF(Q9="","",IF(MIN(MOD(Q9,32),32-MOD(Q9,32))<=0.25,32,IF(MIN(MOD(Q9,16),16-MOD(Q9,16))<=0.25,16,IF(MIN(MOD(Q9,8),8-MOD(Q9,8))<=0.25,8,"")))) | V9: =IF(OR(Q9="",T9=""),"",IF(MIN(MOD((Q9+T9),32),32-MOD((Q9+T9),32))<=0.25,32,IF(MIN(MOD((Q9+T9),16),16-MOD((Q9+T9),16))<=0.25,16,IF(MIN(MOD((Q9+T9),8),8-MOD((Q9+T9),8))<=0.25,8,""))))
O10: =IF(A10="","",IFERROR(INDEX(Tracks!$E$2:$E$41,MATCH(A10,Tracks!$A$2:$A$41,0)),"?")) | P10: =IF(A10="","",IFERROR(N(INDEX(Tracks!$F$2:$F$41,MATCH(A10,Tracks!$A$2:$A$41,0))),"")) | Q10: =IF(D10<>"",D10-1,IF(OR(A10="",C10="",N(P10)<=0),"",(N(B10)*60+C10-IFERROR(N(INDEX(Tracks!$G$2:$G$41,MATCH(A10,Tracks!$A$2:$A$41,0))),0))*P10/240)) | R10: =IF(Q10="","",INT(Q10)+1) | S10: =IF(OR(Q10="",D10<>""),"",MIN(4.75,ROUND((Q10-INT(Q10))*16,0)/4+1)) | T10: =IF(OR(E10="",N(P10)<=0),"",E10*P10/240) | U10: =IF(Q10="","",IF(MIN(MOD(Q10,32),32-MOD(Q10,32))<=0.25,32,IF(MIN(MOD(Q10,16),16-MOD(Q10,16))<=0.25,16,IF(MIN(MOD(Q10,8),8-MOD(Q10,8))<=0.25,8,"")))) | V10: =IF(OR(Q10="",T10=""),"",IF(MIN(MOD((Q10+T10),32),32-MOD((Q10+T10),32))<=0.25,32,IF(MIN(MOD((Q10+T10),16),16-MOD((Q10+T10),16))<=0.25,16,IF(MIN(MOD((Q10+T10),8),8-MOD((Q10+T10),8))<=0.25,8,""))))
O11: =IF(A11="","",IFERROR(INDEX(Tracks!$E$2:$E$41,MATCH(A11,Tracks!$A$2:$A$41,0)),"?")) | P11: =IF(A11="","",IFERROR(N(INDEX(Tracks!$F$2:$F$41,MATCH(A11,Tracks!$A$2:$A$41,0))),"")) | Q11: =IF(D11<>"",D11-1,IF(OR(A11="",C11="",N(P11)<=0),"",(N(B11)*60+C11-IFERROR(N(INDEX(Tracks!$G$2:$G$41,MATCH(A11,Tracks!$A$2:$A$41,0))),0))*P11/240)) | R11: =IF(Q11="","",INT(Q11)+1) | S11: =IF(OR(Q11="",D11<>""),"",MIN(4.75,ROUND((Q11-INT(Q11))*16,0)/4+1)) | T11: =IF(OR(E11="",N(P11)<=0),"",E11*P11/240) | U11: =IF(Q11="","",IF(MIN(MOD(Q11,32),32-MOD(Q11,32))<=0.25,32,IF(MIN(MOD(Q11,16),16-MOD(Q11,16))<=0.25,16,IF(MIN(MOD(Q11,8),8-MOD(Q11,8))<=0.25,8,"")))) | V11: =IF(OR(Q11="",T11=""),"",IF(MIN(MOD((Q11+T11),32),32-MOD((Q11+T11),32))<=0.25,32,IF(MIN(MOD((Q11+T11),16),16-MOD((Q11+T11),16))<=0.25,16,IF(MIN(MOD((Q11+T11),8),8-MOD((Q11+T11),8))<=0.25,8,""))))
O12: =IF(A12="","",IFERROR(INDEX(Tracks!$E$2:$E$41,MATCH(A12,Tracks!$A$2:$A$41,0)),"?")) | P12: =IF(A12="","",IFERROR(N(INDEX(Tracks!$F$2:$F$41,MATCH(A12,Tracks!$A$2:$A$41,0))),"")) | Q12: =IF(D12<>"",D12-1,IF(OR(A12="",C12="",N(P12)<=0),"",(N(B12)*60+C12-IFERROR(N(INDEX(Tracks!$G$2:$G$41,MATCH(A12,Tracks!$A$2:$A$41,0))),0))*P12/240)) | R12: =IF(Q12="","",INT(Q12)+1) | S12: =IF(OR(Q12="",D12<>""),"",MIN(4.75,ROUND((Q12-INT(Q12))*16,0)/4+1)) | T12: =IF(OR(E12="",N(P12)<=0),"",E12*P12/240) | U12: =IF(Q12="","",IF(MIN(MOD(Q12,32),32-MOD(Q12,32))<=0.25,32,IF(MIN(MOD(Q12,16),16-MOD(Q12,16))<=0.25,16,IF(MIN(MOD(Q12,8),8-MOD(Q12,8))<=0.25,8,"")))) | V12: =IF(OR(Q12="",T12=""),"",IF(MIN(MOD((Q12+T12),32),32-MOD((Q12+T12),32))<=0.25,32,IF(MIN(MOD((Q12+T12),16),16-MOD((Q12+T12),16))<=0.25,16,IF(MIN(MOD((Q12+T12),8),8-MOD((Q12+T12),8))<=0.25,8,""))))
O13: =IF(A13="","",IFERROR(INDEX(Tracks!$E$2:$E$41,MATCH(A13,Tracks!$A$2:$A$41,0)),"?")) | P13: =IF(A13="","",IFERROR(N(INDEX(Tracks!$F$2:$F$41,MATCH(A13,Tracks!$A$2:$A$41,0))),"")) | Q13: =IF(D13<>"",D13-1,IF(OR(A13="",C13="",N(P13)<=0),"",(N(B13)*60+C13-IFERROR(N(INDEX(Tracks!$G$2:$G$41,MATCH(A13,Tracks!$A$2:$A$41,0))),0))*P13/240)) | R13: =IF(Q13="","",INT(Q13)+1) | S13: =IF(OR(Q13="",D13<>""),"",MIN(4.75,ROUND((Q13-INT(Q13))*16,0)/4+1)) | T13: =IF(OR(E13="",N(P13)<=0),"",E13*P13/240) | U13: =IF(Q13="","",IF(MIN(MOD(Q13,32),32-MOD(Q13,32))<=0.25,32,IF(MIN(MOD(Q13,16),16-MOD(Q13,16))<=0.25,16,IF(MIN(MOD(Q13,8),8-MOD(Q13,8))<=0.25,8,"")))) | V13: =IF(OR(Q13="",T13=""),"",IF(MIN(MOD((Q13+T13),32),32-MOD((Q13+T13),32))<=0.25,32,IF(MIN(MOD((Q13+T13),16),16-MOD((Q13+T13),16))<=0.25,16,IF(MIN(MOD((Q13+T13),8),8-MOD((Q13+T13),8))<=0.25,8,""))))
O14: =IF(A14="","",IFERROR(INDEX(Tracks!$E$2:$E$41,MATCH(A14,Tracks!$A$2:$A$41,0)),"?")) | P14: =IF(A14="","",IFERROR(N(INDEX(Tracks!$F$2:$F$41,MATCH(A14,Tracks!$A$2:$A$41,0))),"")) | Q14: =IF(D14<>"",D14-1,IF(OR(A14="",C14="",N(P14)<=0),"",(N(B14)*60+C14-IFERROR(N(INDEX(Tracks!$G$2:$G$41,MATCH(A14,Tracks!$A$2:$A$41,0))),0))*P14/240)) | R14: =IF(Q14="","",INT(Q14)+1) | S14: =IF(OR(Q14="",D14<>""),"",MIN(4.75,ROUND((Q14-INT(Q14))*16,0)/4+1)) | T14: =IF(OR(E14="",N(P14)<=0),"",E14*P14/240) | U14: =IF(Q14="","",IF(MIN(MOD(Q14,32),32-MOD(Q14,32))<=0.25,32,IF(MIN(MOD(Q14,16),16-MOD(Q14,16))<=0.25,16,IF(MIN(MOD(Q14,8),8-MOD(Q14,8))<=0.25,8,"")))) | V14: =IF(OR(Q14="",T14=""),"",IF(MIN(MOD((Q14+T14),32),32-MOD((Q14+T14),32))<=0.25,32,IF(MIN(MOD((Q14+T14),16),16-MOD((Q14+T14),16))<=0.25,16,IF(MIN(MOD((Q14+T14),8),8-MOD((Q14+T14),8))<=0.25,8,""))))
O15: =IF(A15="","",IFERROR(INDEX(Tracks!$E$2:$E$41,MATCH(A15,Tracks!$A$2:$A$41,0)),"?")) | P15: =IF(A15="","",IFERROR(N(INDEX(Tracks!$F$2:$F$41,MATCH(A15,Tracks!$A$2:$A$41,0))),"")) | Q15: =IF(D15<>"",D15-1,IF(OR(A15="",C15="",N(P15)<=0),"",(N(B15)*60+C15-IFERROR(N(INDEX(Tracks!$G$2:$G$41,MATCH(A15,Tracks!$A$2:$A$41,0))),0))*P15/240)) | R15: =IF(Q15="","",INT(Q15)+1) | S15: =IF(OR(Q15="",D15<>""),"",MIN(4.75,ROUND((Q15-INT(Q15))*16,0)/4+1)) | T15: =IF(OR(E15="",N(P15)<=0),"",E15*P15/240) | U15: =IF(Q15="","",IF(MIN(MOD(Q15,32),32-MOD(Q15,32))<=0.25,32,IF(MIN(MOD(Q15,16),16-MOD(Q15,16))<=0.25,16,IF(MIN(MOD(Q15,8),8-MOD(Q15,8))<=0.25,8,"")))) | V15: =IF(OR(Q15="",T15=""),"",IF(MIN(MOD((Q15+T15),32),32-MOD((Q15+T15),32))<=0.25,32,IF(MIN(MOD((Q15+T15),16),16-MOD((Q15+T15),16))<=0.25,16,IF(MIN(MOD((Q15+T15),8),8-MOD((Q15+T15),8))<=0.25,8,""))))
O16: =IF(A16="","",IFERROR(INDEX(Tracks!$E$2:$E$41,MATCH(A16,Tracks!$A$2:$A$41,0)),"?")) | P16: =IF(A16="","",IFERROR(N(INDEX(Tracks!$F$2:$F$41,MATCH(A16,Tracks!$A$2:$A$41,0))),"")) | Q16: =IF(D16<>"",D16-1,IF(OR(A16="",C16="",N(P16)<=0),"",(N(B16)*60+C16-IFERROR(N(INDEX(Tracks!$G$2:$G$41,MATCH(A16,Tracks!$A$2:$A$41,0))),0))*P16/240)) | R16: =IF(Q16="","",INT(Q16)+1) | S16: =IF(OR(Q16="",D16<>""),"",MIN(4.75,ROUND((Q16-INT(Q16))*16,0)/4+1)) | T16: =IF(OR(E16="",N(P16)<=0),"",E16*P16/240) | U16: =IF(Q16="","",IF(MIN(MOD(Q16,32),32-MOD(Q16,32))<=0.25,32,IF(MIN(MOD(Q16,16),16-MOD(Q16,16))<=0.25,16,IF(MIN(MOD(Q16,8),8-MOD(Q16,8))<=0.25,8,"")))) | V16: =IF(OR(Q16="",T16=""),"",IF(MIN(MOD((Q16+T16),32),32-MOD((Q16+T16),32))<=0.25,32,IF(MIN(MOD((Q16+T16),16),16-MOD((Q16+T16),16))<=0.25,16,IF(MIN(MOD((Q16+T16),8),8-MOD((Q16+T16),8))<=0.25,8,""))))
... O501: =IF(A501="","",IFERROR(INDEX(Tracks!$E$2:$E$41,MATCH(A501,Tracks!$A$2:$A$41,0)),"?")) | P501: =IF(A501="","",IFERROR(N(INDEX(Tracks!$F$2:$F$41,MATCH(A501,Tracks!$A$2:$A$41,0))),"")) | Q501: =IF(D501<>"",D501-1,IF(OR(A501="",C501="",N(P501)<=0),"",(N(B501)*60+C501-IFERROR(N(INDEX(Tracks!$G$2:$G$41,MATCH(A501,Tracks!$A$2:$A$41,0))),0))*P501/240)) | R501: =IF(Q501="","",INT(Q501)+1) | S501: =IF(OR(Q501="",D501<>""),"",MIN(4.75,ROUND((Q501-INT(Q501))*16,0)/4+1)) | T501: =IF(OR(E501="",N(P501)<=0),"",E501*P501/240) | U501: =IF(Q501="","",IF(MIN(MOD(Q501,32),32-MOD(Q501,32))<=0.25,32,IF(MIN(MOD(Q501,16),16-MOD(Q501,16))<=0.25,16,IF(MIN(MOD(Q501,8),8-MOD(Q501,8))<=0.25,8,"")))) | V501: =IF(OR(Q501="",T501=""),"",IF(MIN(MOD((Q501+T501),32),32-MOD((Q501+T501),32))<=0.25,32,IF(MIN(MOD((Q501+T501),16),16-MOD((Q501+T501),16))<=0.25,16,IF(MIN(MOD((Q501+T501),8),8-MOD((Q501+T501),8))<=0.25,8,""))))

Sheet Summary
A1: Summary
A2: Everything here is computed from Log and Sections, and leaves out the example track (EX). Densities need the Sections sheet filled in.
A4: 1. Events by role and genre
A5: Role | B5: Trance 96-99 | C5: Prog house | D5: Goa | E5: Revival | F5: Prog breaks | G5: Other | H5: All
A6: Bed | B6: =COUNTIFS(Log!$G$2:$G$501,$A6,Log!$O$2:$O$501,B$5) -> 0 | C6: =COUNTIFS(Log!$G$2:$G$501,$A6,Log!$O$2:$O$501,C$5) -> 0 | D6: =COUNTIFS(Log!$G$2:$G$501,$A6,Log!$O$2:$O$501,D$5) -> 0 | E6: =COUNTIFS(Log!$G$2:$G$501,$A6,Log!$O$2:$O$501,E$5) -> 0 | F6: =COUNTIFS(Log!$G$2:$G$501,$A6,Log!$O$2:$O$501,F$5) -> 0 | G6: =COUNTIFS(Log!$G$2:$G$501,$A6,Log!$O$2:$O$501,G$5) -> 0 | H6: =SUM(B6:G6) -> 0
A7: Motion | B7: =COUNTIFS(Log!$G$2:$G$501,$A7,Log!$O$2:$O$501,B$5) -> 0 | C7: =COUNTIFS(Log!$G$2:$G$501,$A7,Log!$O$2:$O$501,C$5) -> 0 | D7: =COUNTIFS(Log!$G$2:$G$501,$A7,Log!$O$2:$O$501,D$5) -> 0 | E7: =COUNTIFS(Log!$G$2:$G$501,$A7,Log!$O$2:$O$501,E$5) -> 0 | F7: =COUNTIFS(Log!$G$2:$G$501,$A7,Log!$O$2:$O$501,F$5) -> 0 | G7: =COUNTIFS(Log!$G$2:$G$501,$A7,Log!$O$2:$O$501,G$5) -> 0 | H7: =SUM(B7:G7) -> 0
A8: Transition | B8: =COUNTIFS(Log!$G$2:$G$501,$A8,Log!$O$2:$O$501,B$5) -> 0 | C8: =COUNTIFS(Log!$G$2:$G$501,$A8,Log!$O$2:$O$501,C$5) -> 0 | D8: =COUNTIFS(Log!$G$2:$G$501,$A8,Log!$O$2:$O$501,D$5) -> 0 | E8: =COUNTIFS(Log!$G$2:$G$501,$A8,Log!$O$2:$O$501,E$5) -> 0 | F8: =COUNTIFS(Log!$G$2:$G$501,$A8,Log!$O$2:$O$501,F$5) -> 0 | G8: =COUNTIFS(Log!$G$2:$G$501,$A8,Log!$O$2:$O$501,G$5) -> 0 | H8: =SUM(B8:G8) -> 0
A9: Punctuation | B9: =COUNTIFS(Log!$G$2:$G$501,$A9,Log!$O$2:$O$501,B$5) -> 0 | C9: =COUNTIFS(Log!$G$2:$G$501,$A9,Log!$O$2:$O$501,C$5) -> 0 | D9: =COUNTIFS(Log!$G$2:$G$501,$A9,Log!$O$2:$O$501,D$5) -> 0 | E9: =COUNTIFS(Log!$G$2:$G$501,$A9,Log!$O$2:$O$501,E$5) -> 0 | F9: =COUNTIFS(Log!$G$2:$G$501,$A9,Log!$O$2:$O$501,F$5) -> 0 | G9: =COUNTIFS(Log!$G$2:$G$501,$A9,Log!$O$2:$O$501,G$5) -> 0 | H9: =SUM(B9:G9) -> 0
A10: Ear candy | B10: =COUNTIFS(Log!$G$2:$G$501,$A10,Log!$O$2:$O$501,B$5) -> 0 | C10: =COUNTIFS(Log!$G$2:$G$501,$A10,Log!$O$2:$O$501,C$5) -> 0 | D10: =COUNTIFS(Log!$G$2:$G$501,$A10,Log!$O$2:$O$501,D$5) -> 0 | E10: =COUNTIFS(Log!$G$2:$G$501,$A10,Log!$O$2:$O$501,E$5) -> 0 | F10: =COUNTIFS(Log!$G$2:$G$501,$A10,Log!$O$2:$O$501,F$5) -> 0 | G10: =COUNTIFS(Log!$G$2:$G$501,$A10,Log!$O$2:$O$501,G$5) -> 0 | H10: =SUM(B10:G10) -> 0
A11: Total | B11: =SUM(B6:B10) -> 0 | C11: =SUM(C6:C10) -> 0 | D11: =SUM(D6:D10) -> 0 | E11: =SUM(E6:E10) -> 0 | F11: =SUM(F6:F10) -> 0 | G11: =SUM(G6:G10) -> 0 | H11: =SUM(H6:H10) -> 0
A13: 2. Events per 8 bars, by role and section (all tracks)
A14: Role | B14: Intro | C14: Build | D14: Breakdown | E14: Drop | F14: Main | G14: Outro | H14: Interlude
A15: Bed | B15: =IFERROR(COUNTIFS(Log!$G$2:$G$501,$A15,Log!$F$2:$F$501,B$14,Log!$O$2:$O$501,"<>Example")/(B$20/8),"-") -> - | C15: =IFERROR(COUNTIFS(Log!$G$2:$G$501,$A15,Log!$F$2:$F$501,C$14,Log!$O$2:$O$501,"<>Example")/(C$20/8),"-") -> - | D15: =IFERROR(COUNTIFS(Log!$G$2:$G$501,$A15,Log!$F$2:$F$501,D$14,Log!$O$2:$O$501,"<>Example")/(D$20/8),"-") -> - | E15: =IFERROR(COUNTIFS(Log!$G$2:$G$501,$A15,Log!$F$2:$F$501,E$14,Log!$O$2:$O$501,"<>Example")/(E$20/8),"-") -> - | F15: =IFERROR(COUNTIFS(Log!$G$2:$G$501,$A15,Log!$F$2:$F$501,F$14,Log!$O$2:$O$501,"<>Example")/(F$20/8),"-") -> - | G15: =IFERROR(COUNTIFS(Log!$G$2:$G$501,$A15,Log!$F$2:$F$501,G$14,Log!$O$2:$O$501,"<>Example")/(G$20/8),"-") -> - | H15: =IFERROR(COUNTIFS(Log!$G$2:$G$501,$A15,Log!$F$2:$F$501,H$14,Log!$O$2:$O$501,"<>Example")/(H$20/8),"-") -> -
A16: Motion | B16: =IFERROR(COUNTIFS(Log!$G$2:$G$501,$A16,Log!$F$2:$F$501,B$14,Log!$O$2:$O$501,"<>Example")/(B$20/8),"-") -> - | C16: =IFERROR(COUNTIFS(Log!$G$2:$G$501,$A16,Log!$F$2:$F$501,C$14,Log!$O$2:$O$501,"<>Example")/(C$20/8),"-") -> - | D16: =IFERROR(COUNTIFS(Log!$G$2:$G$501,$A16,Log!$F$2:$F$501,D$14,Log!$O$2:$O$501,"<>Example")/(D$20/8),"-") -> - | E16: =IFERROR(COUNTIFS(Log!$G$2:$G$501,$A16,Log!$F$2:$F$501,E$14,Log!$O$2:$O$501,"<>Example")/(E$20/8),"-") -> - | F16: =IFERROR(COUNTIFS(Log!$G$2:$G$501,$A16,Log!$F$2:$F$501,F$14,Log!$O$2:$O$501,"<>Example")/(F$20/8),"-") -> - | G16: =IFERROR(COUNTIFS(Log!$G$2:$G$501,$A16,Log!$F$2:$F$501,G$14,Log!$O$2:$O$501,"<>Example")/(G$20/8),"-") -> - | H16: =IFERROR(COUNTIFS(Log!$G$2:$G$501,$A16,Log!$F$2:$F$501,H$14,Log!$O$2:$O$501,"<>Example")/(H$20/8),"-") -> -
A17: Transition | B17: =IFERROR(COUNTIFS(Log!$G$2:$G$501,$A17,Log!$F$2:$F$501,B$14,Log!$O$2:$O$501,"<>Example")/(B$20/8),"-") -> - | C17: =IFERROR(COUNTIFS(Log!$G$2:$G$501,$A17,Log!$F$2:$F$501,C$14,Log!$O$2:$O$501,"<>Example")/(C$20/8),"-") -> - | D17: =IFERROR(COUNTIFS(Log!$G$2:$G$501,$A17,Log!$F$2:$F$501,D$14,Log!$O$2:$O$501,"<>Example")/(D$20/8),"-") -> - | E17: =IFERROR(COUNTIFS(Log!$G$2:$G$501,$A17,Log!$F$2:$F$501,E$14,Log!$O$2:$O$501,"<>Example")/(E$20/8),"-") -> - | F17: =IFERROR(COUNTIFS(Log!$G$2:$G$501,$A17,Log!$F$2:$F$501,F$14,Log!$O$2:$O$501,"<>Example")/(F$20/8),"-") -> - | G17: =IFERROR(COUNTIFS(Log!$G$2:$G$501,$A17,Log!$F$2:$F$501,G$14,Log!$O$2:$O$501,"<>Example")/(G$20/8),"-") -> - | H17: =IFERROR(COUNTIFS(Log!$G$2:$G$501,$A17,Log!$F$2:$F$501,H$14,Log!$O$2:$O$501,"<>Example")/(H$20/8),"-") -> -
A18: Punctuation | B18: =IFERROR(COUNTIFS(Log!$G$2:$G$501,$A18,Log!$F$2:$F$501,B$14,Log!$O$2:$O$501,"<>Example")/(B$20/8),"-") -> - | C18: =IFERROR(COUNTIFS(Log!$G$2:$G$501,$A18,Log!$F$2:$F$501,C$14,Log!$O$2:$O$501,"<>Example")/(C$20/8),"-") -> - | D18: =IFERROR(COUNTIFS(Log!$G$2:$G$501,$A18,Log!$F$2:$F$501,D$14,Log!$O$2:$O$501,"<>Example")/(D$20/8),"-") -> - | E18: =IFERROR(COUNTIFS(Log!$G$2:$G$501,$A18,Log!$F$2:$F$501,E$14,Log!$O$2:$O$501,"<>Example")/(E$20/8),"-") -> - | F18: =IFERROR(COUNTIFS(Log!$G$2:$G$501,$A18,Log!$F$2:$F$501,F$14,Log!$O$2:$O$501,"<>Example")/(F$20/8),"-") -> - | G18: =IFERROR(COUNTIFS(Log!$G$2:$G$501,$A18,Log!$F$2:$F$501,G$14,Log!$O$2:$O$501,"<>Example")/(G$20/8),"-") -> - | H18: =IFERROR(COUNTIFS(Log!$G$2:$G$501,$A18,Log!$F$2:$F$501,H$14,Log!$O$2:$O$501,"<>Example")/(H$20/8),"-") -> -
A19: Ear candy | B19: =IFERROR(COUNTIFS(Log!$G$2:$G$501,$A19,Log!$F$2:$F$501,B$14,Log!$O$2:$O$501,"<>Example")/(B$20/8),"-") -> - | C19: =IFERROR(COUNTIFS(Log!$G$2:$G$501,$A19,Log!$F$2:$F$501,C$14,Log!$O$2:$O$501,"<>Example")/(C$20/8),"-") -> - | D19: =IFERROR(COUNTIFS(Log!$G$2:$G$501,$A19,Log!$F$2:$F$501,D$14,Log!$O$2:$O$501,"<>Example")/(D$20/8),"-") -> - | E19: =IFERROR(COUNTIFS(Log!$G$2:$G$501,$A19,Log!$F$2:$F$501,E$14,Log!$O$2:$O$501,"<>Example")/(E$20/8),"-") -> - | F19: =IFERROR(COUNTIFS(Log!$G$2:$G$501,$A19,Log!$F$2:$F$501,F$14,Log!$O$2:$O$501,"<>Example")/(F$20/8),"-") -> - | G19: =IFERROR(COUNTIFS(Log!$G$2:$G$501,$A19,Log!$F$2:$F$501,G$14,Log!$O$2:$O$501,"<>Example")/(G$20/8),"-") -> - | H19: =IFERROR(COUNTIFS(Log!$G$2:$G$501,$A19,Log!$F$2:$F$501,H$14,Log!$O$2:$O$501,"<>Example")/(H$20/8),"-") -> -
A20: Bars logged | B20: =SUMIFS(Sections!$E$2:$E$201,Sections!$B$2:$B$201,B$14,Sections!$A$2:$A$201,"<>EX") -> 0 | C20: =SUMIFS(Sections!$E$2:$E$201,Sections!$B$2:$B$201,C$14,Sections!$A$2:$A$201,"<>EX") -> 0 | D20: =SUMIFS(Sections!$E$2:$E$201,Sections!$B$2:$B$201,D$14,Sections!$A$2:$A$201,"<>EX") -> 0 | E20: =SUMIFS(Sections!$E$2:$E$201,Sections!$B$2:$B$201,E$14,Sections!$A$2:$A$201,"<>EX") -> 0 | F20: =SUMIFS(Sections!$E$2:$E$201,Sections!$B$2:$B$201,F$14,Sections!$A$2:$A$201,"<>EX") -> 0 | G20: =SUMIFS(Sections!$E$2:$E$201,Sections!$B$2:$B$201,G$14,Sections!$A$2:$A$201,"<>EX") -> 0 | H20: =SUMIFS(Sections!$E$2:$E$201,Sections!$B$2:$B$201,H$14,Sections!$A$2:$A$201,"<>EX") -> 0
A22: 3. Phrase lines and length, by role
A23: Role | B23: Events | C23: Start on a line | D23: Share | E23: End on a line | F23: Share | G23: Mean length (bars)
A24: Bed | B24: =COUNTIFS(Log!$G$2:$G$501,$A24,Log!$O$2:$O$501,"<>Example") -> 0 | C24: =COUNTIFS(Log!$G$2:$G$501,$A24,Log!$O$2:$O$501,"<>Example",Log!$U$2:$U$501,">0") -> 0 | D24: =IFERROR(C24/B24,"-") -> - | E24: =COUNTIFS(Log!$G$2:$G$501,$A24,Log!$O$2:$O$501,"<>Example",Log!$V$2:$V$501,">0") -> 0 | F24: =IFERROR(E24/B24,"-") -> - | G24: =IFERROR(AVERAGEIFS(Log!$T$2:$T$501,Log!$G$2:$G$501,$A24,Log!$O$2:$O$501,"<>Example"),"-") -> -
A25: Motion | B25: =COUNTIFS(Log!$G$2:$G$501,$A25,Log!$O$2:$O$501,"<>Example") -> 0 | C25: =COUNTIFS(Log!$G$2:$G$501,$A25,Log!$O$2:$O$501,"<>Example",Log!$U$2:$U$501,">0") -> 0 | D25: =IFERROR(C25/B25,"-") -> - | E25: =COUNTIFS(Log!$G$2:$G$501,$A25,Log!$O$2:$O$501,"<>Example",Log!$V$2:$V$501,">0") -> 0 | F25: =IFERROR(E25/B25,"-") -> - | G25: =IFERROR(AVERAGEIFS(Log!$T$2:$T$501,Log!$G$2:$G$501,$A25,Log!$O$2:$O$501,"<>Example"),"-") -> -
A26: Transition | B26: =COUNTIFS(Log!$G$2:$G$501,$A26,Log!$O$2:$O$501,"<>Example") -> 0 | C26: =COUNTIFS(Log!$G$2:$G$501,$A26,Log!$O$2:$O$501,"<>Example",Log!$U$2:$U$501,">0") -> 0 | D26: =IFERROR(C26/B26,"-") -> - | E26: =COUNTIFS(Log!$G$2:$G$501,$A26,Log!$O$2:$O$501,"<>Example",Log!$V$2:$V$501,">0") -> 0 | F26: =IFERROR(E26/B26,"-") -> - | G26: =IFERROR(AVERAGEIFS(Log!$T$2:$T$501,Log!$G$2:$G$501,$A26,Log!$O$2:$O$501,"<>Example"),"-") -> -
A27: Punctuation | B27: =COUNTIFS(Log!$G$2:$G$501,$A27,Log!$O$2:$O$501,"<>Example") -> 0 | C27: =COUNTIFS(Log!$G$2:$G$501,$A27,Log!$O$2:$O$501,"<>Example",Log!$U$2:$U$501,">0") -> 0 | D27: =IFERROR(C27/B27,"-") -> - | E27: =COUNTIFS(Log!$G$2:$G$501,$A27,Log!$O$2:$O$501,"<>Example",Log!$V$2:$V$501,">0") -> 0 | F27: =IFERROR(E27/B27,"-") -> - | G27: =IFERROR(AVERAGEIFS(Log!$T$2:$T$501,Log!$G$2:$G$501,$A27,Log!$O$2:$O$501,"<>Example"),"-") -> -
A28: Ear candy | B28: =COUNTIFS(Log!$G$2:$G$501,$A28,Log!$O$2:$O$501,"<>Example") -> 0 | C28: =COUNTIFS(Log!$G$2:$G$501,$A28,Log!$O$2:$O$501,"<>Example",Log!$U$2:$U$501,">0") -> 0 | D28: =IFERROR(C28/B28,"-") -> - | E28: =COUNTIFS(Log!$G$2:$G$501,$A28,Log!$O$2:$O$501,"<>Example",Log!$V$2:$V$501,">0") -> 0 | F28: =IFERROR(E28/B28,"-") -> - | G28: =IFERROR(AVERAGEIFS(Log!$T$2:$T$501,Log!$G$2:$G$501,$A28,Log!$O$2:$O$501,"<>Example"),"-") -> -
A29: A line is the start of an 8-, 16- or 32-bar phrase, within one beat. Transitions should mostly end on one; ear candy mostly shouldn't.
A31: 4. Material by genre
A32: Material | B32: Trance 96-99 | C32: Prog house | D32: Goa | E32: Revival | F32: Prog breaks | G32: Other
A33: Noise | B33: =COUNTIFS(Log!$H$2:$H$501,$A33,Log!$O$2:$O$501,B$32) -> 0 | C33: =COUNTIFS(Log!$H$2:$H$501,$A33,Log!$O$2:$O$501,C$32) -> 0 | D33: =COUNTIFS(Log!$H$2:$H$501,$A33,Log!$O$2:$O$501,D$32) -> 0 | E33: =COUNTIFS(Log!$H$2:$H$501,$A33,Log!$O$2:$O$501,E$32) -> 0 | F33: =COUNTIFS(Log!$H$2:$H$501,$A33,Log!$O$2:$O$501,F$32) -> 0 | G33: =COUNTIFS(Log!$H$2:$H$501,$A33,Log!$O$2:$O$501,G$32) -> 0
A34: Resonant | B34: =COUNTIFS(Log!$H$2:$H$501,$A34,Log!$O$2:$O$501,B$32) -> 0 | C34: =COUNTIFS(Log!$H$2:$H$501,$A34,Log!$O$2:$O$501,C$32) -> 0 | D34: =COUNTIFS(Log!$H$2:$H$501,$A34,Log!$O$2:$O$501,D$32) -> 0 | E34: =COUNTIFS(Log!$H$2:$H$501,$A34,Log!$O$2:$O$501,E$32) -> 0 | F34: =COUNTIFS(Log!$H$2:$H$501,$A34,Log!$O$2:$O$501,F$32) -> 0 | G34: =COUNTIFS(Log!$H$2:$H$501,$A34,Log!$O$2:$O$501,G$32) -> 0
A35: Inharmonic | B35: =COUNTIFS(Log!$H$2:$H$501,$A35,Log!$O$2:$O$501,B$32) -> 0 | C35: =COUNTIFS(Log!$H$2:$H$501,$A35,Log!$O$2:$O$501,C$32) -> 0 | D35: =COUNTIFS(Log!$H$2:$H$501,$A35,Log!$O$2:$O$501,D$32) -> 0 | E35: =COUNTIFS(Log!$H$2:$H$501,$A35,Log!$O$2:$O$501,E$32) -> 0 | F35: =COUNTIFS(Log!$H$2:$H$501,$A35,Log!$O$2:$O$501,F$32) -> 0 | G35: =COUNTIFS(Log!$H$2:$H$501,$A35,Log!$O$2:$O$501,G$32) -> 0
A36: Tonal | B36: =COUNTIFS(Log!$H$2:$H$501,$A36,Log!$O$2:$O$501,B$32) -> 0 | C36: =COUNTIFS(Log!$H$2:$H$501,$A36,Log!$O$2:$O$501,C$32) -> 0 | D36: =COUNTIFS(Log!$H$2:$H$501,$A36,Log!$O$2:$O$501,D$32) -> 0 | E36: =COUNTIFS(Log!$H$2:$H$501,$A36,Log!$O$2:$O$501,E$32) -> 0 | F36: =COUNTIFS(Log!$H$2:$H$501,$A36,Log!$O$2:$O$501,F$32) -> 0 | G36: =COUNTIFS(Log!$H$2:$H$501,$A36,Log!$O$2:$O$501,G$32) -> 0
A37: Voice | B37: =COUNTIFS(Log!$H$2:$H$501,$A37,Log!$O$2:$O$501,B$32) -> 0 | C37: =COUNTIFS(Log!$H$2:$H$501,$A37,Log!$O$2:$O$501,C$32) -> 0 | D37: =COUNTIFS(Log!$H$2:$H$501,$A37,Log!$O$2:$O$501,D$32) -> 0 | E37: =COUNTIFS(Log!$H$2:$H$501,$A37,Log!$O$2:$O$501,E$32) -> 0 | F37: =COUNTIFS(Log!$H$2:$H$501,$A37,Log!$O$2:$O$501,F$32) -> 0 | G37: =COUNTIFS(Log!$H$2:$H$501,$A37,Log!$O$2:$O$501,G$32) -> 0
A38: Field | B38: =COUNTIFS(Log!$H$2:$H$501,$A38,Log!$O$2:$O$501,B$32) -> 0 | C38: =COUNTIFS(Log!$H$2:$H$501,$A38,Log!$O$2:$O$501,C$32) -> 0 | D38: =COUNTIFS(Log!$H$2:$H$501,$A38,Log!$O$2:$O$501,D$32) -> 0 | E38: =COUNTIFS(Log!$H$2:$H$501,$A38,Log!$O$2:$O$501,E$32) -> 0 | F38: =COUNTIFS(Log!$H$2:$H$501,$A38,Log!$O$2:$O$501,F$32) -> 0 | G38: =COUNTIFS(Log!$H$2:$H$501,$A38,Log!$O$2:$O$501,G$32) -> 0
A39: Cymbal | B39: =COUNTIFS(Log!$H$2:$H$501,$A39,Log!$O$2:$O$501,B$32) -> 0 | C39: =COUNTIFS(Log!$H$2:$H$501,$A39,Log!$O$2:$O$501,C$32) -> 0 | D39: =COUNTIFS(Log!$H$2:$H$501,$A39,Log!$O$2:$O$501,D$32) -> 0 | E39: =COUNTIFS(Log!$H$2:$H$501,$A39,Log!$O$2:$O$501,E$32) -> 0 | F39: =COUNTIFS(Log!$H$2:$H$501,$A39,Log!$O$2:$O$501,F$32) -> 0 | G39: =COUNTIFS(Log!$H$2:$H$501,$A39,Log!$O$2:$O$501,G$32) -> 0
A40: Other | B40: =COUNTIFS(Log!$H$2:$H$501,$A40,Log!$O$2:$O$501,B$32) -> 0 | C40: =COUNTIFS(Log!$H$2:$H$501,$A40,Log!$O$2:$O$501,C$32) -> 0 | D40: =COUNTIFS(Log!$H$2:$H$501,$A40,Log!$O$2:$O$501,D$32) -> 0 | E40: =COUNTIFS(Log!$H$2:$H$501,$A40,Log!$O$2:$O$501,E$32) -> 0 | F40: =COUNTIFS(Log!$H$2:$H$501,$A40,Log!$O$2:$O$501,F$32) -> 0 | G40: =COUNTIFS(Log!$H$2:$H$501,$A40,Log!$O$2:$O$501,G$32) -> 0
A42: 5. Space by role
A43: Space | B43: Bed | C43: Motion | D43: Transition | E43: Punctuation | F43: Ear candy
A44: Dry | B44: =COUNTIFS(Log!$J$2:$J$501,$A44,Log!$G$2:$G$501,B$43,Log!$O$2:$O$501,"<>Example") -> 0 | C44: =COUNTIFS(Log!$J$2:$J$501,$A44,Log!$G$2:$G$501,C$43,Log!$O$2:$O$501,"<>Example") -> 0 | D44: =COUNTIFS(Log!$J$2:$J$501,$A44,Log!$G$2:$G$501,D$43,Log!$O$2:$O$501,"<>Example") -> 0 | E44: =COUNTIFS(Log!$J$2:$J$501,$A44,Log!$G$2:$G$501,E$43,Log!$O$2:$O$501,"<>Example") -> 0 | F44: =COUNTIFS(Log!$J$2:$J$501,$A44,Log!$G$2:$G$501,F$43,Log!$O$2:$O$501,"<>Example") -> 0
A45: Reverb | B45: =COUNTIFS(Log!$J$2:$J$501,$A45,Log!$G$2:$G$501,B$43,Log!$O$2:$O$501,"<>Example") -> 0 | C45: =COUNTIFS(Log!$J$2:$J$501,$A45,Log!$G$2:$G$501,C$43,Log!$O$2:$O$501,"<>Example") -> 0 | D45: =COUNTIFS(Log!$J$2:$J$501,$A45,Log!$G$2:$G$501,D$43,Log!$O$2:$O$501,"<>Example") -> 0 | E45: =COUNTIFS(Log!$J$2:$J$501,$A45,Log!$G$2:$G$501,E$43,Log!$O$2:$O$501,"<>Example") -> 0 | F45: =COUNTIFS(Log!$J$2:$J$501,$A45,Log!$G$2:$G$501,F$43,Log!$O$2:$O$501,"<>Example") -> 0
...

Sheet Tracks
A1: ID | B1: Artist | C1: Title | D1: Year | E1: Genre | F1: BPM | G1: First downbeat (s) | H1: Length (bars) | I1: Version / source | J1: Notes
A2: EX | B2: Example | C2: Delete me when you start | E2: Example | F2: 138 | G2: 0.5 | H2: 184 | J2: Used by the example rows; the summary ignores it.
A3: T1 | B3: Cass & Slide | C3: Perception | D3: 1999 | E3: Prog house | J3: Tempo not confirmed: tap it.
A4: T2 | B4: Taucher | C4: Waters | D4: 1996 | E4: Trance 96-99 | I4: Which mix? (Phase III is 8:10) | J4: Tempo not confirmed: tap it.
A5: T3 | B5: Bedrock | C5: Set in Stone | D5: 1997 | E5: Prog house | I5: Original, 11:04 | J5: One upload says 122 BPM, the era norm is 125-130: check.
A6: T4 | B6: Oprofessionell | C6: Gen Z | D6: 2022 | E6: Revival | F6: 153 | I6: Ute.Rec UTE008 | J6: BPM from decks.de; check against the track.
A7: T5 | B7: T.G.ViRUS | C7: KiloMix '98 | D7: 1998 | E7: Other | F7: 143 | H7: 547 | I7: ReBirth 2.0 demo song | J7: Tempo and length from the .rbs file. Expect almost no textures: a baseline.
A8: T6
A9: T7
A10: T8
A11: T9
A12: T10
A13: T11
A14: T12
A15: T13
A16: T14
A17: T15
A18: T16
A19: T17
... A41: T39

Sheet Sections
A1: Track | B1: Section | C1: First bar | D1: Last bar | E1: Bars | F1: Notes
A2: EX | B2: Intro | C2: 1 | D2: 64 | E2: =IF(OR(C2="",D2=""),"",D2-C2+1) -> 64
A3: EX | B3: Main | C3: 65 | D3: 96 | E3: =IF(OR(C3="",D3=""),"",D3-C3+1) -> 32
A4: EX | B4: Breakdown | C4: 97 | D4: 112 | E4: =IF(OR(C4="",D4=""),"",D4-C4+1) -> 16
A5: EX | B5: Build | C5: 113 | D5: 120 | E5: =IF(OR(C5="",D5=""),"",D5-C5+1) -> 8
A6: EX | B6: Drop | C6: 121 | D6: 184 | E6: =IF(OR(C6="",D6=""),"",D6-C6+1) -> 64
E7: =IF(OR(C7="",D7=""),"",D7-C7+1)
E8: =IF(OR(C8="",D8=""),"",D8-C8+1)
E9: =IF(OR(C9="",D9=""),"",D9-C9+1)
E10: =IF(OR(C10="",D10=""),"",D10-C10+1)
E11: =IF(OR(C11="",D11=""),"",D11-C11+1)
E12: =IF(OR(C12="",D12=""),"",D12-C12+1)
E13: =IF(OR(C13="",D13=""),"",D13-C13+1)
E14: =IF(OR(C14="",D14=""),"",D14-C14+1)
E15: =IF(OR(C15="",D15=""),"",D15-C15+1)
E16: =IF(OR(C16="",D16=""),"",D16-C16+1)
E17: =IF(OR(C17="",D17=""),"",D17-C17+1)
E18: =IF(OR(C18="",D18=""),"",D18-C18+1)
... E201: =IF(OR(C201="",D201=""),"",D201-C201+1)

Sheet Lists
A1: Genre | B1: Section | C1: Role | D1: Material | E1: Movement | F1: Space | G1: Level | H1: Variation
A2: Trance 96-99 | B2: Intro | C2: Bed | D2: Noise | E2: Static | F2: Dry | G2: Foreground | H2: One-off
A3: Prog house | B3: Build | C3: Motion | D3: Resonant | E3: Up | F3: Reverb | G3: Mid | H3: Repeats same
A4: Goa | B4: Breakdown | C4: Transition | D4: Inharmonic | E4: Down | F4: Delay throw | G4: Background | H4: Repeats varied
A5: Revival | B5: Drop | C5: Punctuation | D5: Tonal | E5: Up-down | F5: Reverb + delay
A6: Prog breaks | B6: Main | C6: Ear candy | D6: Voice | E6: Random | F6: Wide / panned
A7: Other | B7: Outro | D7: Field | E7: Rhythmic | F7: Autopan
A8: Example | B8: Interlude | D8: Cymbal
D9: Other
